#VRML_SIM R2021a utf8
WorldInfo {
  coordinateSystem "NUE"
}
Viewpoint {
  orientation 0.816911894310475 0.46608260607001883 0.33973807742590634 4.876958503598818
  position -1.081276706163958 3.941972682380378 1.0664106287662232
}
TexturedBackground {
}
TexturedBackgroundLight {
}
DEF Floor Floor {
  rotation 0 1 0 0.7853996938995746
  size 4 4
  tileSize 0.4 0.4
}
DEF Walls Group {
  children [
    DEF Wall Solid {
      translation 0.9898 0.075 -0.4242
      rotation 0 1 0 -0.7853996938995746
      children [
        DEF Wall Shape {
          appearance PBRAppearance {
            baseColor 0.392157 0.392157 0.392157
            roughness 1
            metalness 0
          }
          geometry Box {
            size 1.2 0.15 0.015
          }
        }
      ]
      name "solid(6)"
      boundingObject USE Wall
    }
    DEF Wall Solid {
      translation -0.9898 0.075 0.4242
      rotation 0 1 0 -0.7853996938995746
      children [
        DEF Wall Shape {
          appearance PBRAppearance {
            baseColor 0.392157 0.392157 0.392157
            roughness 1
            metalness 0
          }
          geometry Box {
            size 1.2 0.15 0.015
          }
        }
      ]
      name "solid(9)"
      boundingObject USE Wall
    }
    DEF Wall Solid {
      translation 0.9898 0.075 0.4242
      rotation 0 1 0 0.7853996938995746
      children [
        DEF Wall Shape {
          appearance PBRAppearance {
            baseColor 0.392157 0.392157 0.392157
            roughness 1
            metalness 0
          }
          geometry Box {
            size 1.2 0.15 0.015
          }
        }
      ]
      name "solid(5)"
      boundingObject USE Wall
    }
    DEF Wall Solid {
      translation -0.9898 0.075 -0.4242
      rotation 0 1 0 0.7853996938995746
      children [
        DEF Wall Shape {
          appearance PBRAppearance {
            baseColor 0.392157 0.392157 0.392157
            roughness 1
            metalness 0
          }
          geometry Box {
            size 1.2 0.15 0.015
          }
        }
      ]
      name "solid(8)"
      boundingObject USE Wall
    }
    DEF Wall Solid {
      translation 0.2828 0.075 -0.5656
      rotation 0 1 0 0.7853996938995746
      children [
        DEF Wall Shape {
          appearance PBRAppearance {
            baseColor 0.392157 0.392157 0.392157
            roughness 1
            metalness 0
          }
          geometry Box {
            size 0.8 0.15 0.015
          }
        }
      ]
      name "solid(7)"
      boundingObject USE Wall
    }
    DEF Wall Solid {
      translation -0.2828 0.075 0.5656
      rotation 0 1 0 0.7853996938995746
      children [
        DEF Wall Shape {
          appearance PBRAppearance {
            baseColor 0.392157 0.392157 0.392157
            roughness 1
            metalness 0
          }
          geometry Box {
            size 0.8 0.15 0.015
          }
        }
      ]
      name "solid(10)"
      boundingObject USE Wall
    }
    DEF Wall Solid {
      translation -0.2828 0.075 -0.5656
      rotation 0 1 0 -0.7853996938995746
      children [
        DEF Wall Shape {
          appearance PBRAppearance {
            baseColor 0.392157 0.392157 0.392157
            roughness 1
            metalness 0
          }
          geometry Box {
            size 0.8 0.15 0.015
          }
        }
      ]
      name "solid(16)"
      boundingObject USE Wall
    }
    DEF Wall Solid {
      translation 0.2828 0.075 0.5656
      rotation 0 1 0 -0.7853996938995746
      children [
        DEF Wall Shape {
          appearance PBRAppearance {
            baseColor 0.392157 0.392157 0.392157
            roughness 1
            metalness 0
          }
          geometry Box {
            size 0.8 0.15 0.015
          }
        }
      ]
      name "solid(19)"
      boundingObject USE Wall
    }
    DEF Wall Solid {
      translation 0.707 0.075 0.1414
      rotation 0 1 0 0.7853996938995746
      children [
        DEF Wall Shape {
          appearance PBRAppearance {
            baseColor 0.392157 0.392157 0.392157
            roughness 1
            metalness 0
          }
          geometry Box {
            size 0.4 0.15 0.015
          }
        }
      ]
      name "solid(2)"
      boundingObject USE Wall
    }
    DEF Wall Solid {
      translation -0.707 0.075 -0.1414
      rotation 0 1 0 0.7853996938995746
      children [
        DEF Wall Shape {
          appearance PBRAppearance {
            baseColor 0.392157 0.392157 0.392157
            roughness 1
            metalness 0
          }
          geometry Box {
            size 0.4 0.15 0.015
          }
        }
      ]
      name "solid(13)"
      boundingObject USE Wall
    }
    DEF Wall Solid {
      translation 0.4242 0.075 -0.1414
      rotation 0 1 0 0.7853996938995746
      children [
        DEF Wall Shape {
          appearance PBRAppearance {
            baseColor 0.392157 0.392157 0.392157
            roughness 1
            metalness 0
          }
          geometry Box {
            size 0.4 0.15 0.015
          }
        }
      ]
      name "solid(4)"
      boundingObject USE Wall
    }
    DEF Wall Solid {
      translation -0.4242 0.075 0.1414
      rotation 0 1 0 0.7853996938995746
      children [
        DEF Wall Shape {
          appearance PBRAppearance {
            baseColor 0.392157 0.392157 0.392157
            roughness 1
            metalness 0
          }
          geometry Box {
            size 0.4 0.15 0.015
          }
        }
      ]
      name "solid(11)"
      boundingObject USE Wall
    }
    DEF Wall Solid {
      translation 0.707 0.075 -0.1414
      rotation 0 1 0 2.3561996938995744
      children [
        DEF Wall Shape {
          appearance PBRAppearance {
            baseColor 0.392157 0.392157 0.392157
            roughness 1
            metalness 0
          }
          geometry Box {
            size 0.4 0.15 0.015
          }
        }
      ]
      name "solid(3)"
      boundingObject USE Wall
    }
    DEF Wall Solid {
      translation -0.707 0.075 0.1414
      rotation 0 1 0 2.3561996938995744
      children [
        DEF Wall Shape {
          appearance PBRAppearance {
            baseColor 0.392157 0.392157 0.392157
            roughness 1
            metalness 0
          }
          geometry Box {
            size 0.4 0.15 0.015
          }
        }
      ]
      name "solid(12)"
      boundingObject USE Wall
    }
    DEF Wall Solid {
      translation 0.424 0.075 0.1414
      rotation 0 1 0 2.3561996938995744
      children [
        DEF Wall Shape {
          appearance PBRAppearance {
            baseColor 0.392157 0.392157 0.392157
            roughness 1
            metalness 0
          }
          geometry Box {
            size 0.4 0.15 0.015
          }
        }
      ]
      name "solid(17)"
      boundingObject USE Wall
    }
    DEF Wall Solid {
      translation -0.4242 0.075 -0.1414
      rotation 0 1 0 2.3561996938995744
      children [
        DEF Wall Shape {
          appearance PBRAppearance {
            baseColor 0.392157 0.392157 0.392157
            roughness 1
            metalness 0
          }
          geometry Box {
            size 0.4 0.15 0.015
          }
        }
      ]
      name "solid(20)"
      boundingObject USE Wall
    }
  ]
}
DEF ROBOT_RED Robot {
  translation -0.21211 0 0.21209
  rotation 0 1 0 2.3561996938995744
  children [
    Lidar {
    }
    DEF MAIN_BODY Transform {
      translation 0 0.0415 0
      children [
        Shape {
          appearance PBRAppearance {
            baseColor 0.196078 0.196078 0.196078
            roughness 1
            metalness 0
          }
          geometry DEF BODY Cylinder {
            height 0.08
            radius 0.045
          }
        }
      ]
    }
    DEF LEFT_WHEEL HingeJoint {
      jointParameters HingeJointParameters {
        position 716.4543820994643
        axis -1 0 0
        anchor 0 0.025 0
      }
      device [
        RotationalMotor {
          name "left wheel motor"
        }
      ]
      endPoint DEF LEFT_WHEEL Solid {
        translation -0.02999999999999918 0.025 0
        rotation 1 0 0 4.813412919008581
        children [
          DEF WHEEL Transform {
            rotation 0 0 1 1.57
            children [
              Shape {
                appearance PBRAppearance {
                  baseColor 0.196078 0.196078 0.196078
                  roughness 1
                  metalness 0
                }
                geometry Cylinder {
                  height 0.01
                  radius 0.025
                }
              }
            ]
          }
        ]
        name "left wheel"
        boundingObject DEF WHEEL Transform {
          rotation 0 0 1 1.57
          children [
            Shape {
              appearance PBRAppearance {
                baseColor 0 0 1
                roughness 1
                metalness 0
              }
              geometry Cylinder {
                height 0.01
                radius 0.025
              }
            }
          ]
        }
        physics DEF PHYSICS_WHEEL Physics {
          density -1
          mass 0.05
        }
      }
    }
    DEF RIGHT_WHEEL HingeJoint {
      jointParameters HingeJointParameters {
        position -20.216961239977245
        axis -1 0 0
        anchor 0 0.025 0
      }
      device [
        RotationalMotor {
          name "right wheel motor"
        }
      ]
      endPoint DEF RIGHT_WHEEL Solid {
        translation 0.030000000000000013 0.025 0
        rotation -0.9999999999999999 0 0 0.32842998874109613
        children [
          DEF WHEEL Transform {
            rotation 0 0 1 1.57
            children [
              Shape {
                appearance PBRAppearance {
                  baseColor 0.196078 0.196078 0.196078
                  roughness 1
                  metalness 0
                }
                geometry Cylinder {
                  height 0.01
                  radius 0.025
                }
              }
            ]
          }
        ]
        name "right wheel"
        boundingObject USE WHEEL
        physics DEF PHYSICS_WHEEL Physics {
          density -1
          mass 0.05
        }
      }
    }
    DEF DS0 DistanceSensor {
      translation 0.045 0.063 0
      children [
        DEF INFRARED Transform {
          rotation 0 0 1 1.57
          children [
            Shape {
              appearance PBRAppearance {
                baseColor 0.975691 0.981481 0.0252992
                roughness 1
                metalness 0
              }
              geometry Cylinder {
                height 0.004
                radius 0.008
              }
            }
          ]
        }
      ]
      name "ds0"
      lookupTable [
        0 1000 0
        0.01 1000 0.01
        0.1 500 0.01
        0.9 50 0.01
        1 10 0
      ]
      aperture 1
    }
    DEF DS1 DistanceSensor {
      translation 0.0225 0.063 -0.039
      rotation 0 1 0 1.0472003061004251
      children [
        DEF INFRARED Transform {
          rotation 0 0 1 1.57
          children [
            Shape {
              appearance PBRAppearance {
                baseColor 0.975691 0.981481 0.0252992
                roughness 1
                metalness 0
              }
              geometry Cylinder {
                height 0.004
                radius 0.008
              }
            }
          ]
        }
      ]
      name "ds1"
      lookupTable [
        0 1000 0
        0.01 1000 0.01
        0.1 500 0.01
        0.9 50 0.01
        1 10 0
      ]
      aperture 1
    }
    DEF DS4 DistanceSensor {
      translation 0.039 0.063 -0.0233
      rotation 0 -1 0 -0.5236053071795865
      children [
        DEF INFRARED Transform {
          rotation 0 0 1 1.57
          children [
            Shape {
              appearance PBRAppearance {
                baseColor 0.975691 0.981481 0.0252992
                roughness 1
                metalness 0
              }
              geometry Cylinder {
                height 0.004
                radius 0.008
              }
            }
          ]
        }
      ]
      name "ds4"
      lookupTable [
        0 1000 0
        0.01 1000 0.01
        0.1 500 0.01
        0.9 50 0.01
        1 10 0
      ]
      aperture 1
    }
    DEF DS2 DistanceSensor {
      translation -0.0225 0.063 -0.039
      rotation 0 1 0 2.094399693899575
      children [
        DEF INFRARED Transform {
          rotation 0 0 1 1.57
          children [
            Shape {
              appearance PBRAppearance {
                baseColor 0.975691 0.981481 0.0252992
                roughness 1
                metalness 0
              }
              geometry Cylinder {
                height 0.004
                radius 0.008
              }
            }
          ]
        }
      ]
      name "ds2"
      lookupTable [
        0 1000 0
        0.01 1000 0.01
        0.1 500 0.01
        0.9 50 0.01
        1 10 0
      ]
      aperture 1
    }
    DEF DS3 DistanceSensor {
      translation -0.045 0.063 0
      rotation 0 1 0 3.141592653589793
      children [
        DEF INFRARED Transform {
          rotation 0 0 1 1.57
          children [
            Shape {
              appearance PBRAppearance {
                baseColor 0.975691 0.981481 0.0252992
                roughness 1
                metalness 0
              }
              geometry Cylinder {
                height 0.004
                radius 0.008
              }
            }
          ]
        }
      ]
      name "ds3"
      lookupTable [
        0 1000 0
        0.01 1000 0.01
        0.1 500 0.01
        0.9 50 0.01
        1 10 0
      ]
      aperture 1
    }
    DEF DS5 DistanceSensor {
      translation -0.039 0.063 -0.022
      rotation 0 -1 0 -2.6179953071795863
      children [
        DEF INFRARED Transform {
          rotation 0 0 1 1.57
          children [
            Shape {
              appearance PBRAppearance {
                baseColor 0.975691 0.981481 0.0252992
                roughness 1
                metalness 0
              }
              geometry Cylinder {
                height 0.004
                radius 0.008
              }
            }
          ]
        }
      ]
      name "ds5"
      lookupTable [
        0 1000 0
        0.01 1000 0.01
        0.1 500 0.01
        0.9 50 0.01
        1 10 0
      ]
      aperture 1
    }
    DEF CAMERA Camera {
      translation 0 0.045 -0.045
      children [
        Transform {
          rotation 1 0 0 1.57
          children [
            Shape {
              appearance PBRAppearance {
                baseColor 1 0 0
                roughness 1
                metalness 0
              }
              geometry Cylinder {
                height 0.01
                radius 0.007
              }
            }
          ]
        }
      ]
      fieldOfView 1.047
      width 80
      height 60
      antiAliasing TRUE
      noise 0.04
    }
    DEF LED LED {
      translation 0 0.08 0
      children [
        Group {
          children [
            Shape {
              appearance PBRAppearance {
                baseColor 1 0 0
                roughness 1
                metalness 0
              }
              geometry DEF LED_SHAPE Sphere {
                radius 0.01
              }
            }
            PointLight {
              attenuation 0 0 1
              color 0 0 0
              intensity 0.5
              location 0 0.03 0
              on FALSE
              castShadows TRUE
            }
          ]
        }
      ]
      color [
        1 0 0
        0 1 0
        0 0 1
        1 1 0
        0 1 1
        1 0 1
        1 0.647059 0
        0.627451 0.12549 0.941176
        0.545098 0.411765 0.0784314
      ]
    }
  ]
  name "ROBOT_RED"
  boundingObject DEF MYBOT_BOUNDING Transform {
    translation 0 0.0415 0
    children [
      DEF BODY Cylinder {
        height 0.08
        radius 0.045
      }
    ]
  }
  physics DEF MYBOT_PHYSICS Physics {
    density -1
    mass 0.5
  }
  controller "NMP_Controller"
}
